Workbook

Sheet DASHBOARD

Sheet MONTH
B1: Admissions | C1: Discharges | D1: Deaths | E1: ALOS | F1: BTR | G1: BTI | H1: Bed Occupancy Rate | I1: Deaths Rate
A2: JANUARY | B2: =Monthly!D13 -> 398 | C2: =Monthly!E13 -> 330 | D2: =Monthly!F13 -> 11 | E2: =Monthly!L13 -> 7.568915 | F2: =Monthly!N13 -> 1.9157303 | G2: =Monthly!M13 -> 8.6129032 | H2: =Monthly!O13 -> 46.774194 | I2: =Monthly!P13 -> 3.2258065
A3: FEBRUARY
A4: MARCH
A5: APRIL
A6: MAY
A7: JUNE
A8: JULY
A9: AUGUST
A10: SEPTEMBER
A11: OCTOBER
A12: NOVEMBER
A13: DECEMBER
A15: Death Rate By Wards | B15: Male | C15: Female | D15: Children | E15: Block F | F15: Block G | G15: Block H | H15: NICU | I15: A&E
A16: JANUARY | B16: =Monthly!P4 -> #DIV/0! | C16: =Monthly!P6 -> #DIV/0! | D16: =Monthly!P5 -> #DIV/0! | E16: =Monthly!P7 -> 0 | F16: =Monthly!P9 -> 0 | G16: =Monthly!P10 -> 0 | H16: =Monthly!P12 -> 2.3255814 | I16: =(Monthly!P8+Monthly!P11)/2 -> 23.492723
A17: FEBRUARY
A18: MARCH
A19: APRIL
A20: MAY
A21: JUNE
A22: JULY
A23: AUGUST
A24: SEPTEMBER
A25: OCTOBER
A26: NOVEMBER
A27: DECEMBER

Sheet Monthly
A1: GHANA HEALTH SERVICE
A2: MONTHLY BED UTILIZATION FORM - JANUARY, 2025
A3: WARD | B3: Patients on bed at the beginning of the month | C3: Bed Compliment | D3: Admissions | E3: Discharges | F3: Deaths | G3: Deaths <24Hrs | H3: Patient Days | I3: Transfer In | J3: Transfer Out | K3: Average Daily Bed Occupancy | L3: Average Length of Stay | M3: Bed Turnover Interval | N3: Bed Turnover Rate | O3: Percentage of Occupancy | P3: Death Rate
A4: Male Medical | B4: =Male!H4 -> 18 | C4: 32 | D4: =Male!B38 -> 0 | E4: =Male!C38 -> 0 | F4: =Male!D38 -> 0 | G4: =Male!E38 -> 0 | H4: =Male!H38 -> 558 | I4: =Male!F38 -> 0 | J4: =Male!G38 -> 0 | K4: =H4/31 -> 18 | L4: =H4/(E4+F4) -> #DIV/0! | M4: =((C4*31)-H4)/(E4+F4) -> #DIV/0! | N4: =(E4+F4)/C4 -> 0 | O4: =H4*100/(C4*31) -> 56.25 | P4: =F4*100/(E4+F4) -> #DIV/0!
A5: Paediatry | B5: =Paediatric!H4 -> 6 | C5: 27 | D5: =Paediatric!B38 -> 0 | E5: =Paediatric!C38 -> 0 | F5: =Paediatric!D38 -> 0 | G5: =Paediatric!E38 -> 0 | H5: =Paediatric!H38 -> 186 | I5: =Paediatric!F38 -> 0 | J5: =Paediatric!G38 -> 0 | K5: =H5/31 -> 6 | L5: =H5/(E5+F5) -> #DIV/0! | M5: =((C5*31)-H5)/(E5+F5) -> #DIV/0! | N5: =(E5+F5)/C5 -> 0 | O5: =H5*100/(C5*31) -> 22.222222 | P5: =F5*100/(E5+F5) -> #DIV/0!
A6: Female Medical | B6: =Female!H4 -> 15 | C6: 28 | D6: =Female!B38 -> 0 | E6: =Female!C38 -> 0 | F6: =Female!D38 -> 0 | G6: =Female!E38 -> 0 | H6: =Female!H38 -> 465 | I6: =Female!F38 -> 0 | J6: =Female!G38 -> 0 | K6: =H6/31 -> 15 | L6: =H6/(E6+F6) -> #DIV/0! | M6: =((C6*31)-H6)/(E6+F6) -> #DIV/0! | N6: =(E6+F6)/C6 -> 0 | O6: =H6*100/(C6*31) -> 53.571429 | P6: =F6*100/(E6+F6) -> #DIV/0!
A7: Block F | B7: ='BLK F'!H4 -> 12 | C7: 20 | D7: ='BLK F'!B38 -> 82 | E7: ='BLK F'!C38 -> 81 | F7: ='BLK F'!D38 -> 0 | G7: ='BLK F'!E38 -> 0 | H7: ='BLK F'!H38 -> 277 | I7: ='BLK F'!F38 -> 1 | J7: ='BLK F'!G38 -> 7 | K7: =H7/31 -> 8.9354839 | L7: =H7/(E7+F7) -> 3.4197531 | M7: =((C7*31)-H7)/(E7+F7) -> 4.2345679 | N7: =(E7+F7)/C7 -> 4.05 | O7: =H7*100/(C7*31) -> 44.677419 | P7: =F7*100/(E7+F7) -> 0
A8: Male Emergency | B8: ='Male Emergency'!H4 -> 2 | C8: 10 | D8: ='Male Emergency'!B38 -> 63 | E8: ='Male Emergency'!C38 -> 31 | F8: ='Male Emergency'!D38 -> 6 | G8: ='Male Emergency'!E38 -> 7 | H8: ='Male Emergency'!H38 -> 123 | I8: ='Male Emergency'!F38 -> 0 | J8: ='Male Emergency'!G38 -> 27 | K8: =H8/31 -> 3.9677419 | L8: =H8/(E8+F8) -> 3.3243243 | M8: =((C8*31)-H8)/(E8+F8) -> 5.0540541 | N8: =(E8+F8)/C8 -> 3.7 | O8: =H8*100/(C8*31) -> 39.677419 | P8: =F8*100/(E8+F8) -> 16.216216
A9: Block G | B9: ='BLK G'!H4 -> 8 | C9: 14 | D9: ='BLK G'!B38 -> 95 | E9: ='BLK G'!C38 -> 90 | F9: ='BLK G'!D38 -> 0 | G9: ='BLK G'!E38 -> 0 | H9: ='BLK G'!H38 -> 199 | I9: ='BLK G'!F38 -> 23 | J9: ='BLK G'!G38 -> 28 | K9: =H9/31 -> 6.4193548 | L9: =H9/(E9+F9) -> 2.2111111 | M9: =((C9*31)-H9)/(E9+F9) -> 2.6111111 | N9: =(E9+F9)/C9 -> 6.4285714 | O9: =H9*100/(C9*31) -> 45.852535 | P9: =F9*100/(E9+F9) -> 0
A10: Block H | B10: ='BLK H'!H4 -> 12 | C10: 22 | D10: ='BLK H'!B38 -> 69 | E10: ='BLK H'!C38 -> 77 | F10: ='BLK H'!D38 -> 0 | G10: ='BLK H'!E38 -> 0 | H10: ='BLK H'!H38 -> 361 | I10: ='BLK H'!F38 -> 31 | J10: ='BLK H'!G38 -> 20 | K10: =H10/31 -> 11.645161 | L10: =H10/(E10+F10) -> 4.6883117 | M10: =((C10*31)-H10)/(E10+F10) -> 4.1688312 | N10: =(E10+F10)/C10 -> 3.5 | O10: =H10*100/(C10*31) -> 52.932551 | P10: =F10*100/(E10+F10) -> 0
A11: Female Emergency | B11: ='Female Emergency'!H4 -> 4 | C11: 10 | D11: ='Female Emergency'!B38 -> 45 | E11: ='Female Emergency'!C38 -> 9 | F11: ='Female Emergency'!D38 -> 4 | G11: ='Female Emergency'!E38 -> 1 | H11: ='Female Emergency'!H38 -> 96 | I11: ='Female Emergency'!F38 -> 0 | J11: ='Female Emergency'!G38 -> 33 | K11: =H11/31 -> 3.0967742 | L11: =H11/(E11+F11) -> 7.3846154 | M11: =((C11*31)-H11)/(E11+F11) -> 16.461538 | N11: =(E11+F11)/C11 -> 1.3 | O11: =H11*100/(C11*31) -> 30.967742 | P11: =F11*100/(E11+F11) -> 30.769231
A12: Neonatal Ward | B12: =Neonatal!H4 -> 11 | C12: 15 | D12: =Neonatal!B38 -> 44 | E12: =Neonatal!C38 -> 42 | F12: =Neonatal!D38 -> 1 | G12: =Neonatal!E38 -> 0 | H12: =Neonatal!H38 -> 316 | I12: =Neonatal!F38 -> 0 | J12: =Neonatal!G38 -> 1 | K12: =H12/31 -> 10.193548 | L12: =H12/(E12+F12) -> 7.3488372 | M12: =((C12*31)-H12)/(E12+F12) -> 3.4651163 | N12: =(E12+F12)/C12 -> 2.8666667 | O12: =H12*100/(C12*31) -> 67.956989 | P12: =F12*100/(E12+F12) -> 2.3255814
A13: TOTAL | B13: =SUM(B4:B12) -> 88 | C13: =SUM(C4:C12) -> 178 | D13: =SUM(D4:D12) -> 398 | E13: =SUM(E4:E12) -> 330 | F13: =SUM(F4:F12) -> 11 | G13: =SUM(G4:G12) -> 8 | H13: =SUM(H4:H12) -> 2581 | I13: =SUM(I4:I12) -> 55 | J13: =SUM(J4:J12) -> 116 | K13: =H13/31 -> 83.258065 | L13: =H13/(E13+F13) -> 7.568915 | M13: =((C13*31)-H13)/(E13+F13) -> 8.6129032 | N13: =(E13+F13)/C13 -> 1.9157303 | O13: =H13*100/(C13*31) -> 46.774194 | P13: =F13*100/(E13+F13) -> 3.2258065
A14: Emergency | B14: =B8+B11 -> 6 | C14: =C8+C11 -> 20 | D14: =D8+D11 -> 108 | E14: =E8+E11 -> 40 | F14: =F8+F11 -> 10 | G14: =G8+G11 -> 8 | H14: =H8+H11 -> 219 | I14: =I8+I11 -> 0 | J14: =J8+J11 -> 60 | K14: =H14/31 -> 7.0645161 | L14: =H14/(E14+F14) -> 4.38 | M14: =((C14*31)-H14)/(E14+F14) -> 8.02 | N14: =(E14+F14)/C14 -> 2.5 | O14: =H14*100/(C14*31) -> 35.322581 | P14: =F14*100/(E14+F14) -> 20 | Q14: =G14/(F14+G14)*100 -> 44.444444
A16: GHANA HEALTH SERVICE
A17: MONTHLY BED UTILIZATION FORM - FEBRUARY, 2025
A18: WARD | B18: Patients on bed at the beginning of the month | C18: Bed Compliment | D18: Admissions | E18: Discharges | F18: Deaths | G18: Deaths <24Hrs | H18: Patient Days | I18: Transfer In | J18: Transfer Out | K18: Average Daily Bed Occupancy | L18: Average Length of Stay | M18: Bed Turnover Interval | N18: Bed Turnover Rate | O18: Percentage of Occupancy | P18: Death Rate
A19: Male Medical | B19: =Male!H37 -> 18 | C19: 32 | D19: =Male!B76 -> 0 | E19: =Male!C76 -> 0 | F19: =Male!D76 -> 0 | G19: =Male!E76 -> 0 | H19: =Male!H76 -> 522 | I19: =Male!F76 -> 0 | J19: =Male!G76 -> 0 | K19: =H19/28 -> 18.642857 | L19: =H19/(E19+F19) -> #DIV/0! | M19: =((C19*28)-H19)/(E19+F19) -> #DIV/0! | N19: =(E19+F19)/C19 -> 0 | O19: =H19*100/(C19*28) -> 58.258929 | P19: =F19*100/(E19+F19) -> #DIV/0!
A20: Paediatry | B20: =Paediatric!H37 -> 6 | C20: 27 | D20: =Paediatric!B76 -> 0 | E20: =Paediatric!C76 -> 0 | F20: =Paediatric!D76 -> 0 | G20: =Paediatric!E76 -> 0 | H20: =Paediatric!H76 -> 174 | I20: =Paediatric!F76 -> 0 | J20: =Paediatric!G76 -> 0 | K20: =H20/28 -> 6.2142857 | L20: =H20/(E20+F20) -> #DIV/0! | M20: =((C20*28)-H20)/(E20+F20) -> #DIV/0! | N20: =(E20+F20)/C20 -> 0 | O20: =H20*100/(C20*28) -> 23.015873 | P20: =F20*100/(E20+F20) -> #DIV/0!
A21: Female Medical | B21: =Female!H37 -> 15 | C21: 28 | D21: =Female!B76 -> 67 | E21: =Female!C76 -> 0 | F21: =Female!D76 -> 0 | G21: =Female!E76 -> 0 | H21: =Female!H76 -> 435 | I21: =Female!F76 -> 0 | J21: =Female!G76 -> 0 | K21: =H21/28 -> 15.535714 | L21: =H21/(E21+F21) -> #DIV/0! | M21: =((C21*28)-H21)/(E21+F21) -> #DIV/0! | N21: =(E21+F21)/C21 -> 0 | O21: =H21*100/(C21*28) -> 55.484694 | P21: =F21*100/(E21+F21) -> #DIV/0!
A22: Block F | B22: ='BLK F'!H37 -> 7 | C22: 20 | D22: ='BLK F'!B76 -> 65 | E22: ='BLK F'!C76 -> 63 | F22: ='BLK F'!D76 -> 0 | G22: ='BLK F'!E76 -> 0 | H22: ='BLK F'!H76 -> 165 | I22: ='BLK F'!F76 -> 0 | J22: ='BLK F'!G76 -> 2 | K22: =H22/28 -> 5.8928571 | L22: =H22/(E22+F22) -> 2.6190476 | M22: =((C22*28)-H22)/(E22+F22) -> 6.2698413 | N22: =(E22+F22)/C22 -> 3.15 | O22: =H22*100/(C22*28) -> 29.464286 | P22: =F22*100/(E22+F22) -> 0
A23: Male Emergency | B23: ='Male Emergency'!H37 -> 1 | C23: 10 | D23: ='Male Emergency'!B76 -> 74 | E23: ='Male Emergency'!C76 -> 23 | F23: ='Male Emergency'!D76 -> 5 | G23: ='Male Emergency'!E76 -> 5 | H23: ='Male Emergency'!H76 -> 128 | I23: ='Male Emergency'!F76 -> 0 | J23: ='Male Emergency'!G76 -> 42 | K23: =H23/28 -> 4.5714286 | L23: =H23/(E23+F23) -> 4.5714286 | M23: =((C23*28)-H23)/(E23+F23) -> 5.4285714 | N23: =(E23+F23)/C23 -> 2.8 | O23: =H23*100/(C23*28) -> 45.714286 | P23: =F23*100/(E23+F23) -> 17.857143
A24: Block G | B24: ='BLK G'!H37 -> 8 | C24: 14 | D24: ='BLK G'!B76 -> 84 | E24: ='BLK G'!C76 -> 71 | F24: ='BLK G'!D76 -> 0 | G24: ='BLK G'!E76 -> 0 | H24: ='BLK G'!H76 -> 213 | I24: ='BLK G'!F76 -> 22 | J24: ='BLK G'!G76 -> 33 | K24: =H24/28 -> 7.6071429 | L24: =H24/(E24+F24) -> 3 | M24: =((C24*28)-H24)/(E24+F24) -> 2.5211268 | N24: =(E24+F24)/C24 -> 5.0714286 | O24: =H24*100/(C24*28) -> 54.336735 | P24: =F24*100/(E24+F24) -> 0
A25: Block H | B25: ='BLK H'!H37 -> 15 | C25: 22 | D25: ='BLK H'!B76 -> 62 | E25: ='BLK H'!C76 -> 74 | F25: ='BLK H'!D76 -> 0 | G25: ='BLK H'!E76 -> 0 | H25: ='BLK H'!H76 -> 371 | I25: ='BLK H'!F76 -> 33 | J25: ='BLK H'!G76 -> 20 | K25: =H25/28 -> 13.25 | L25: =H25/(E25+F25) -> 5.0135135 | M25: =((C25*28)-H25)/(E25+F25) -> 3.3108108 | N25: =(E25+F25)/C25 -> 3.3636364 | O25: =H25*100/(C25*28) -> 60.227273 | P25: =F25*100/(E25+F25) -> 0
A26: Female Emergency | B26: ='Female Emergency'!H37 -> 3 | C26: 10 | D26: ='Female Emergency'!B76 -> 41 | E26: ='Female Emergency'!C76 -> 9 | F26: ='Female Emergency'!D76 -> 4 | G26: ='Female Emergency'!E76 -> 1 | H26: ='Female Emergency'!H76 -> 91 | I26: ='Female Emergency'!F76 -> 0 | J26: ='Female Emergency'!G76 -> 29 | K26: =H26/28 -> 3.25 | L26: =H26/(E26+F26) -> 7 | M26: =((C26*28)-H26)/(E26+F26) -> 14.538462 | N26: =(E26+F26)/C26 -> 1.3 | O26: =H26*100/(C26*28) -> 32.5 | P26: =F26*100/(E26+F26) -> 30.769231
A27: Neonatal Ward | B27: =Neonatal!H37 -> 11 | C27: 15 | D27: =Neonatal!B76 -> 61 | E27: =Neonatal!C76 -> 48 | F27: =Neonatal!D76 -> 3 | G27: =Neonatal!E76 -> 0 | H27: =Neonatal!H76 -> 520 | I27: =Neonatal!F76 -> 0 | J27: =Neonatal!G76 -> 0 | K27: =H27/28 -> 18.571429 | L27: =H27/(E27+F27) -> 10.196078 | M27: =((C27*28)-H27)/(E27+F27) -> -1.9607843 | N27: =(E27+F27)/C27 -> 3.4 | O27: =H27*100/(C27*28) -> 123.80952 | P27: =F27*100/(E27+F27) -> 5.8823529
A28: TOTAL | B28: =SUM(B19:B27) -> 84 | C28: =SUM(C19:C27) -> 178 | D28: =SUM(D19:D27) -> 454 | E28: =SUM(E19:E27) -> 288 | F28: =SUM(F19:F27) -> 12 | G28: =SUM(G19:G27) -> 6 | H28: =SUM(H19:H27) -> 2619 | I28: =SUM(I19:I27) -> 55 | J28: =SUM(J19:J27) -> 126 | K28: =H28/28 -> 93.535714 | L28: =H28/(E28+F28) -> 8.73 | M28: =((C28*28)-H28)/(E28+F28) -> 7.8833333 | N28: =(E28+F28)/C28 -> 1.6853933 | O28: =H28*100/(C28*28) -> 52.548154 | P28: =F28*100/(E28+F28) -> 4
A29: Emergency | B29: =B23+B26 -> 4 | C29: =C23+C26 -> 20 | D29: =D23+D26 -> 115 | E29: =E23+E26 -> 32 | F29: =F23+F26 -> 9 | G29: =G23+G26 -> 6 | H29: =H23+H26 -> 219 | I29: =I23+I26 -> 0 | J29: =J23+J26 -> 71 | K29: =H29/28 -> 7.8214286 | L29: =H29/(E29+F29) -> 5.3414634 | M29: =((C29*28)-H29)/(E29+F29) -> 8.3170732 | N29: =(E29+F29)/C29 -> 2.05 | O29: =H29*100/(C29*28) -> 39.107143 | P29: =F29*100/(E29+F29) -> 21.95122 | Q29: =G29/(F29+G29)*100 -> 40
A31: GHANA HEALTH SERVICE
A32: MONTHLY BED UTILIZATION FORM - MARCH, 2025
A33: WARD | B33: Patients on bed at the beginning of the month | C33: Bed Compliment | D33: Admissions | E33: Discharges | F33: Deaths | G33: Deaths <24Hrs | H33: Patient Days | I33: Transfer In | J33: Transfer Out | K33: Average Daily Bed Occupancy | L33: Average Length of Stay | M33: Bed Turnover Interval | N33: Bed Turnover Rate | O33: Percentage of Occupancy | P33: Death Rate
A34: Male Medical | B34: =Male!H82 -> 18 | C34: 32 | D34: =Male!B116 -> 0 | E34: =Male!C116 -> 0 | F34: =Male!D116 -> 0 | G34: =Male!E116 -> 0 | H34: =Male!H116 -> 558 | I34: =Male!F116 -> 0 | J34: =Male!G116 -> 0 | K34: =H34/31 -> 18 | L34: =H34/(E34+F34) -> #DIV/0! | M34: =((C34*31)-H34)/(E34+F34) -> #DIV/0! | N34: =(E34+F34)/C34 -> 0 | O34: =H34*100/(C34*31) -> 56.25 | P34: =F34*100/(E34+F34) -> #DIV/0!
A35: Paediatry | B35: =Paediatric!H82 -> 6 | C35: 27 | D35: =Paediatric!B116 -> 0 | E35: =Paediatric!C116 -> 0 | F35: =Paediatric!D116 -> 0 | G35: =Paediatric!E116 -> 0 | H35: =Paediatric!H116 -> 186 | I35: =Paediatric!F116 -> 0 | J35: =Paediatric!G116 -> 0 | K35: =H35/31 -> 6 | L35: =H35/(E35+F35) -> #DIV/0! | M35: =((C35*31)-H35)/(E35+F35) -> #DIV/0! | N35: =(E35+F35)/C35 -> 0 | O35: =H35*100/(C35*31) -> 22.222222 | P35: =F35*100/(E35+F35) -> #DIV/0!
A36: Female Medical | B36: =Female!H82 -> 15 | C36: 28 | D36: =Female!B116 -> 0 | E36: =Female!C116 -> 0 | F36: =Female!D116 -> 0 | G36: =Female!E116 -> 0 | H36: =Female!H116 -> 465 | I36: =Female!F116 -> 0 | J36: =Female!G116 -> 0 | K36: =H36/31 -> 15 | L36: =H36/(E36+F36) -> #DIV/0! | M36: =((C36*31)-H36)/(E36+F36) -> #DIV/0! | N36: =(E36+F36)/C36 -> 0 | O36: =H36*100/(C36*31) -> 53.571429 | P36: =F36*100/(E36+F36) -> #DIV/0!
A37: Block F | B37: ='BLK F'!H82 -> 7 | C37: 20 | D37: ='BLK F'!B116 -> 78 | E37: ='BLK F'!C116 -> 76 | F37: ='BLK F'!D116 -> 0 | G37: ='BLK F'!E116 -> 0 | H37: ='BLK F'!H116 -> 303 | I37: ='BLK F'!F116 -> 5 | J37: ='BLK F'!G116 -> 1 | K37: =H37/31 -> 9.7741935 | L37: =H37/(E37+F37) -> 3.9868421 | M37: =((C37*31)-H37)/(E37+F37) -> 4.1710526 | N37: =(E37+F37)/C37 -> 3.8 | O37: =H37*100/(C37*31) -> 48.870968 | P37: =F37*100/(E37+F37) -> 0
A38: Male Emergency | B38: ='Male Emergency'!H82 -> 5 | C38: 10 | D38: ='Male Emergency'!B116 -> 53 | E38: ='Male Emergency'!C116 -> 17 | F38: ='Male Emergency'!D116 -> 2 | G38: ='Male Emergency'!E116 -> 3 | H38: ='Male Emergency'!H116 -> 126 | I38: ='Male Emergency'!F116 -> 0 | J38: ='Male Emergency'!G116 -> 36 | K38: =H38/31 -> 4.0645161 | L38: =H38/(E38+F38) -> 6.6315789 | M38: =((C38*31)-H38)/(E38+F38) -> 9.6842105 | N38: =(E38+F38)/C38 -> 1.9 | O38: =H38*100/(C38*31) -> 40.645161 | P38: =F38*100/(E38+F38) -> 10.526316
A39: Block G | B39: ='BLK G'!H82 -> 10 | C39: 14 | D39: ='BLK G'!B116 -> 124 | E39: ='BLK G'!C116 -> 117 | F39: ='BLK G'!D116 -> 0 | G39: ='BLK G'!E116 -> 0 | H39: ='BLK G'!H116 -> 323 | I39: ='BLK G'!F116 -> 31 | J39: ='BLK G'!G116 -> 36 | K39: =H39/31 -> 10.419355 | L39: =H39/(E39+F39) -> 2.7606838 | M39: =((C39*31)-H39)/(E39+F39) -> 0.94871795 | N39: =(E39+F39)/C39 -> 8.3571429 | O39: =H39*100/(C39*31) -> 74.423963 | P39: =F39*100/(E39+F39) -> 0
A40: Block H | B40: ='BLK H'!H82 -> 16 | C40: 22 | D40: ='BLK H'!B116 -> 66 | E40: ='BLK H'!C116 -> 80 | F40: ='BLK H'!D116 -> 0 | G40: ='BLK H'!E116 -> 0 | H40: ='BLK H'!H116 -> 314 | I40: ='BLK H'!F116 -> 37 | J40: ='BLK H'!G116 -> 31 | K40: =H40/31 -> 10.129032 | L40: =H40/(E40+F40) -> 3.925 | M40: =((C40*31)-H40)/(E40+F40) -> 4.6 | N40: =(E40+F40)/C40 -> 3.6363636 | O40: =H40*100/(C40*31) -> 46.041056 | P40: =F40*100/(E40+F40) -> 0
A41: Female Emergency | B41: ='Female Emergency'!H82 -> 2 | C41: 10 | D41: ='Female Emergency'!B116 -> 62 | E41: ='Female Emergency'!C116 -> 21 | F41: ='Female Emergency'!D116 -> 4 | G41: ='Female Emergency'!E116 -> 2 | H41: ='Female Emergency'!H116 -> 52 | I41: ='Female Emergency'!F116 -> 0 | J41: ='Female Emergency'!G116 -> 37 | K41: =H41/31 -> 1.6774194 | L41: =H41/(E41+F41) -> 2.08 | M41: =((C41*31)-H41)/(E41+F41) -> 10.32 | N41: =(E41+F41)/C41 -> 2.5 | O41: =H41*100/(C41*31) -> 16.774194 | P41: =F41*100/(E41+F41) -> 16
A42: Neonatal Ward | B42: =Neonatal!H82 -> 21 | C42: 15 | D42: =Neonatal!B116 -> 42 | E42: =Neonatal!C116 -> 45 | F42: =Neonatal!D116 -> 3 | G42: =Neonatal!E116 -> 0 | H42: =Neonatal!H116 -> 443 | I42: =Neonatal!F116 -> 0 | J42: =Neonatal!G116 -> 0 | K42: =H42/31 -> 14.290323 | L42: =H42/(E42+F42) -> 9.2291667 | M42: =((C42*31)-H42)/(E42+F42) -> 0.45833333 | N42: =(E42+F42)/C42 -> 3.2 | O42: =H42*100/(C42*31) -> 95.268817 | P42: =F42*100/(E42+F42) -> 6.25
...

Sheet Sheet1
A3: WARD | B3: Patients on bed at the beginning of the month | C3: Bed Compliment | D3: Admissions | E3: Discharges | F3: Deaths | G3: Deaths <24Hrs | H3: Patient Days | I3: Transfer In | J3: Transfer Out | K3: Average Daily Bed Occupancy | L3: Average Length of Stay | M3: Bed Turnover Interval | N3: Bed Turnover Rate | O3: Percentage of Occupancy | P3: Death Rate
A4: Block G | B4: 3 | C4: 14 | D4: 964 | E4: 237 | F4: 1 | G4: 0 | H4: 2140 | I4: 0 | J4: 721 | K4: =H4/181 -> 11.823204 | L4: =H4/(E4+F4) -> 8.9915966 | M4: =((C4*181)-H4)/(E4+F4) -> 1.6554622 | N4: =(E4+F4)/C4 -> 17 | O4: =H4*100/(C4*181) -> 84.45146 | P4: =F4*100/(E4+F4) -> 0.42016807
A5: Block H | B5: 7 | C5: 22 | D5: 446 | E5: 1168 | F5: 1 | G5: 0 | H5: 2044 | I5: 722 | J5: 1 | K5: =H5/181 -> 11.292818 | L5: =H5/(E5+F5) -> 1.748503 | M5: =((C5*181)-H5)/(E5+F5) -> 1.6578272 | N5: =(E5+F5)/C5 -> 53.136364 | O5: =H5*100/(C5*181) -> 51.330989 | P5: =F5*100/(E5+F5) -> 0.085543199
B6: =SUM(B4:B5) -> 10 | C6: =SUM(C4:C5) -> 36 | D6: =SUM(D4:D5) -> 1410 | E6: =SUM(E4:E5) -> 1405 | F6: =SUM(F4:F5) -> 2 | G6: =SUM(G4:G5) -> 0 | H6: =SUM(H4:H5) -> 4184 | I6: =SUM(I4:I5) -> 722 | J6: =SUM(J4:J5) -> 722 | K6: =H6/181 -> 23.116022 | L6: =H6/(E6+F6) -> 2.9737029 | M6: =((C6*181)-H6)/(E6+F6) -> 1.6574271 | N6: =(E6+F6)/C6 -> 39.083333 | O6: =H6*100/(C6*181) -> 64.211172 | P6: =F6*100/(E6+F6) -> 0.14214641
A9: WARD | B9: Patients on bed at the beginning of the month | C9: Bed Compliment | D9: Admissions | E9: Discharges | F9: Deaths | G9: Deaths <24Hrs | H9: Patient Days | I9: Transfer In | J9: Transfer Out | K9: Average Daily Bed Occupancy | L9: Average Length of Stay | M9: Bed Turnover Interval | N9: Bed Turnover Rate | O9: Percentage of Occupancy | P9: Death Rate
A10: Male Emergency | B10: 7 | C10: 10 | D10: 35 | E10: 16 | F10: 1 | G10: 3 | H10: 30 | I10: 0 | J10: 25 | K10: =H10/181 -> 0.16574586 | L10: =H10/(E10+F10) -> 1.7647059 | M10: =((C10*181)-H10)/(E10+F10) -> 104.70588 | N10: =(E10+F10)/C10 -> 1.7 | O10: =H10*100/(C10*181) -> 1.6574586 | P10: =F10*100/(E10+F10) -> 5.8823529
A11: Female Emergency | B11: 11 | C11: 10 | D11: 44 | E11: 15 | F11: 3 | G11: 2 | H11: 419 | I11: 0 | J11: 20 | K11: =H11/181 -> 2.3149171 | L11: =H11/(E11+F11) -> 23.277778 | M11: =((C11*181)-H11)/(E11+F11) -> 77.277778 | N11: =(E11+F11)/C11 -> 1.8 | O11: =H11*100/(C11*181) -> 23.149171 | P11: =F11*100/(E11+F11) -> 16.666667
B12: =SUM(B10:B11) -> 18 | C12: =SUM(C10:C11) -> 20 | D12: =SUM(D10:D11) -> 79 | E12: =SUM(E10:E11) -> 31 | F12: =SUM(F10:F11) -> 4 | G12: =SUM(G10:G11) -> 5 | H12: =SUM(H10:H11) -> 449 | I12: =SUM(I10:I11) -> 0 | J12: =SUM(J10:J11) -> 45 | K12: =H12/181 -> 2.480663 | L12: =H12/(E12+F12) -> 12.828571 | M12: =((C12*181)-H12)/(E12+F12) -> 90.6 | N12: =(E12+F12)/C12 -> 1.75 | O12: =H12*100/(C12*181) -> 12.403315 | P12: =F12*100/(E12+F12) -> 11.428571

Sheet Male
A1: GHANA HEALTH SERVICE
A2: DAILY BED UTILIZATION FORM
A3: Hospital:……………………………. | B3: VOLTA REG. HOSP | D3: Ward:………………….. | F3: MALE WARD | G3: MONTH | H3: JANUARY
A4: Number of patients remaining as at last day of previous month | H4: 18
A5: Bed complement | H5: 32
A6: Day of the Month | B6: Admissions | C6: Discharges | D6: Deaths | E6: Deaths <24Hrs | F6: Transfers-In | G6: Transfers-Out | H6: No. of Patients Remaning In Ward
A7: 1 | H7: =H4+B7+F7-(C7+D7+G7)-E7 -> 18
A8: 2 | H8: =H7+B8+F8-(C8+D8+G8)-E8 -> 18
A9: 3 | H9: =H8+B9+F9-(C9+D9+G9)-E9 -> 18
A10: 4 | H10: =H9+B10+F10-(C10+D10+G10)-E10 -> 18
A11: 5 | H11: =H10+B11+F11-(C11+D11+G11)-E11 -> 18
A12: 6 | H12: =H11+B12+F12-(C12+D12+G12)-E12 -> 18
A13: 7 | H13: =H12+B13+F13-(C13+D13+G13)-E13 -> 18
A14: 8 | H14: =H13+B14+F14-(C14+D14+G14)-E14 -> 18
A15: 9 | H15: =H14+B15+F15-(C15+D15+G15)-E15 -> 18
A16: 10 | H16: =H15+B16+F16-(C16+D16+G16)-E16 -> 18
A17: 11 | H17: =H16+B17+F17-(C17+D17+G17)-E17 -> 18
A18: 12 | H18: =H17+B18+F18-(C18+D18+G18)-E18 -> 18
A19: 13 | H19: =H18+B19+F19-(C19+D19+G19)-E19 -> 18
... A37: 31 | H37: =H36+B37+F37-(C37+D37+G37)-E37 -> 18
A38: TOTAL | B38: =SUM(B7:B37)-E38 -> 0 | C38: =SUM(C7:C37) -> 0 | D38: =SUM(D7:D37) -> 0 | E38: =SUM(E7:E37) -> 0 | F38: =SUM(F7:F37) -> 0 | G38: =SUM(G7:G37) -> 0 | H38: =SUM(H7:H37) -> 558
A41: GHANA HEALTH SERVICE
A42: DAILY BED UTILIZATION FORM
A43: Hospital:……………………………. | B43: VOLTA REG. HOSP | D43: Ward:………………….. | F43: MALE WARD | G43: MONTH | H43: FEBRUARY
A44: Number of patients remaining as at last day of previous month | H44: =H37 -> 18
A45: Bed complement | H45: 32
A46: Day of the Month | B46: Admissions | C46: Discharges | D46: Deaths | E46: Deaths <24Hrs | F46: Transfers-In | G46: Transfers-Out | H46: No. of Patients Remaning In Ward
A47: 1 | H47: =H44+B47+F47-(C47+D47+G47)-E47 -> 18
A48: 2 | H48: =H47+B48+F48-(C48+D48+G48)-E48 -> 18
A49: 3 | H49: =H48+B49+F49-(C49+D49+G49)-E49 -> 18
A50: 4 | H50: =H49+B50+F50-(C50+D50+G50)-E50 -> 18
A51: 5 | H51: =H50+B51+F51-(C51+D51+G51)-E51 -> 18
A52: 6 | H52: =H51+B52+F52-(C52+D52+G52)-E52 -> 18
A53: 7 | H53: =H52+B53+F53-(C53+D53+G53)-E53 -> 18
A54: 8 | H54: =H53+B54+F54-(C54+D54+G54)-E54 -> 18
A55: 9 | H55: =H54+B55+F55-(C55+D55+G55)-E55 -> 18
A56: 10 | H56: =H55+B56+F56-(C56+D56+G56)-E56 -> 18
A57: 11 | H57: =H56+B57+F57-(C57+D57+G57)-E57 -> 18
A58: 12 | H58: =H57+B58+F58-(C58+D58+G58)-E58 -> 18
A59: 13 | H59: =H58+B59+F59-(C59+D59+G59)-E59 -> 18
...

Sheet Female
A1: GHANA HEALTH SERVICE
A2: DAILY BED UTILIZATION FORM
A3: Hospital | B3: HOHOE MUNI HOSP | D3: Ward | E3: FEMALE | G3: MONTH | H3: JANUARY
A4: Number of patients remaining as at last day of previous month | H4: 15
A5: Bed complement | H5: 28
A6: Day of the Month | B6: Admissions | C6: Discharges | D6: Deaths | E6: Deaths <24Hrs | F6: Transfers-In | G6: Transfers-Out | H6: No. of Patients Remaning In Ward
A7: 1 | H7: =H4+B7+F7-(C7+D7+G7)-E7 -> 15
A8: 2 | H8: =H7+B8+F8-(C8+D8+G8)-E8 -> 15
A9: 3 | H9: =H8+B9+F9-(C9+D9+G9)-E9 -> 15
A10: 4 | H10: =H9+B10+F10-(C10+D10+G10)-E10 -> 15
A11: 5 | H11: =H10+B11+F11-(C11+D11+G11)-E11 -> 15
A12: 6 | H12: =H11+B12+F12-(C12+D12+G12)-E12 -> 15
A13: 7 | H13: =H12+B13+F13-(C13+D13+G13)-E13 -> 15
A14: 8 | H14: =H13+B14+F14-(C14+D14+G14)-E14 -> 15
A15: 9 | H15: =H14+B15+F15-(C15+D15+G15)-E15 -> 15
A16: 10 | H16: =H15+B16+F16-(C16+D16+G16)-E16 -> 15
A17: 11 | H17: =H16+B17+F17-(C17+D17+G17)-E17 -> 15
A18: 12 | H18: =H17+B18+F18-(C18+D18+G18)-E18 -> 15
A19: 13 | H19: =H18+B19+F19-(C19+D19+G19)-E19 -> 15
... A37: 31 | H37: =H36+B37+F37-(C37+D37+G37)-E37 -> 15
A38: TOTAL | B38: =SUM(B7:B37)-E38 -> 0 | C38: =SUM(C7:C37) -> 0 | D38: =SUM(D7:D37) -> 0 | E38: =SUM(E7:E37) -> 0 | F38: =SUM(F7:F37) -> 0 | G38: =SUM(G7:G37) -> 0 | H38: =SUM(H7:H37) -> 465
A41: GHANA HEALTH SERVICE
A42: DAILY BED UTILIZATION FORM
A43: Hospital | B43: HOHOE MUNI HOSP | D43: Ward | E43: FEMALE | G43: MONTH | H43: FEBRUARY
A44: Number of patients remaining as at last day of previous month | H44: =H37 -> 15
A45: Bed complement | H45: 28
A46: Day of the Month | B46: Admissions | C46: Discharges | D46: Deaths | E46: Deaths <24Hrs | F46: Transfers-In | G46: Transfers-Out | H46: No. of Patients Remaning In Ward
A47: 1 | H47: =H44+B47+F47-(C47+D47+G47)-E47 -> 15
A48: 2 | H48: =H47+B48+F48-(C48+D48+G48)-E48 -> 15
A49: 3 | H49: =H48+B49+F49-(C49+D49+G49)-E49 -> 15
A50: 4 | H50: =H49+B50+F50-(C50+D50+G50)-E50 -> 15
A51: 5 | H51: =H50+B51+F51-(C51+D51+G51)-E51 -> 15
A52: 6 | H52: =H51+B52+F52-(C52+D52+G52)-E52 -> 15
A53: 7 | H53: =H52+B53+F53-(C53+D53+G53)-E53 -> 15
A54: 8 | H54: =H53+B54+F54-(C54+D54+G54)-E54 -> 15
A55: 9 | H55: =H54+B55+F55-(C55+D55+G55)-E55 -> 15
A56: 10 | H56: =H55+B56+F56-(C56+D56+G56)-E56 -> 15
A57: 11 | H57: =H56+B57+F57-(C57+D57+G57)-E57 -> 15
A58: 12 | H58: =H57+B58+F58-(C58+D58+G58)-E58 -> 15
A59: 13 | H59: =H58+B59+F59-(C59+D59+G59)-E59 -> 15
...

Sheet Paediatric
A1: GHANA HEALTH SERVICE
A2: DAILY BED UTILIZATION FORM
A3: Hospital:……………………………. | B3: HOHOE MUNI HOSP | D3: Ward | E3: CHILDREN | G3: MONTH | H3: JANUARY
A4: Number of patients remaining as at last day of previous month | H4: 6
A5: Bed complement | H5: 27
A6: Day of the Month | B6: Admissions | C6: Discharges | D6: Deaths | E6: Deaths <24Hrs | F6: Transfers-In | G6: Transfers-Out | H6: No. of Patients Remaning In Ward
A7: 1 | H7: =H4+B7+F7-(C7+D7+G7)-E7 -> 6
A8: 2 | H8: =H7+B8+F8-(C8+D8+G8)-E8 -> 6
A9: 3 | H9: =H8+B9+F9-(C9+D9+G9)-E9 -> 6
A10: 4 | H10: =H9+B10+F10-(C10+D10+G10)-E10 -> 6
A11: 5 | H11: =H10+B11+F11-(C11+D11+G11)-E11 -> 6
A12: 6 | H12: =H11+B12+F12-(C12+D12+G12)-E12 -> 6
A13: 7 | H13: =H12+B13+F13-(C13+D13+G13)-E13 -> 6
A14: 8 | H14: =H13+B14+F14-(C14+D14+G14)-E14 -> 6
A15: 9 | H15: =H14+B15+F15-(C15+D15+G15)-E15 -> 6
A16: 10 | H16: =H15+B16+F16-(C16+D16+G16)-E16 -> 6
A17: 11 | H17: =H16+B17+F17-(C17+D17+G17)-E17 -> 6
A18: 12 | H18: =H17+B18+F18-(C18+D18+G18)-E18 -> 6
A19: 13 | H19: =H18+B19+F19-(C19+D19+G19)-E19 -> 6
... A37: 31 | H37: =H36+B37+F37-(C37+D37+G37)-E37 -> 6
A38: TOTAL | B38: =SUM(B7:B37)-E38 -> 0 | C38: =SUM(C7:C37) -> 0 | D38: =SUM(D7:D37) -> 0 | E38: =SUM(E7:E37) -> 0 | F38: =SUM(F7:F37) -> 0 | G38: =SUM(G7:G37) -> 0 | H38: =SUM(H7:H37) -> 186
A41: GHANA HEALTH SERVICE
A42: DAILY BED UTILIZATION FORM
A43: Hospital:……………………………. | B43: HOHOE MUNI HOSP | D43: Ward | E43: CHILDREN | G43: MONTH | H43: FEBRUARY
A44: Number of patients remaining as at last day of previous month | H44: =H37 -> 6
A45: Bed complement | H45: 27
A46: Day of the Month | B46: Admissions | C46: Discharges | D46: Deaths | E46: Deaths <24Hrs | F46: Transfers-In | G46: Transfers-Out | H46: No. of Patients Remaning In Ward
A47: 1 | H47: =H44+B47+F47-(C47+D47+G47)-E47 -> 6
A48: 2 | H48: =H47+B48+F48-(C48+D48+G48)-E48 -> 6
A49: 3 | H49: =H48+B49+F49-(C49+D49+G49)-E49 -> 6
A50: 4 | H50: =H49+B50+F50-(C50+D50+G50)-E50 -> 6
A51: 5 | H51: =H50+B51+F51-(C51+D51+G51)-E51 -> 6
A52: 6 | H52: =H51+B52+F52-(C52+D52+G52)-E52 -> 6
A53: 7 | H53: =H52+B53+F53-(C53+D53+G53)-E53 -> 6
A54: 8 | H54: =H53+B54+F54-(C54+D54+G54)-E54 -> 6
A55: 9 | H55: =H54+B55+F55-(C55+D55+G55)-E55 -> 6
A56: 10 | H56: =H55+B56+F56-(C56+D56+G56)-E56 -> 6
A57: 11 | H57: =H56+B57+F57-(C57+D57+G57)-E57 -> 6
A58: 12 | H58: =H57+B58+F58-(C58+D58+G58)-E58 -> 6
A59: 13 | H59: =H58+B59+F59-(C59+D59+G59)-E59 -> 6
...

Sheet BLK F
A1: GHANA HEALTH SERVICE
A2: DAILY BED UTILIZATION FORM
A3: Hospital | B3: HOHOE MUNI HOSP | D3: Ward | E3: BLK F | G3: MONTH | H3: JANUARY
A4: Number of patients remaining as at last day of previous month | H4: 12
A5: Bed complement | H5: 20
A6: Day of the Month | B6: Admissions | C6: Discharges | D6: Deaths | E6: Deaths <24Hrs | F6: Transfers-In | G6: Transfers-Out | H6: No. of Patients Remaning In Ward
A7: 1 | B7: 1 | C7: 5 | H7: =H4+B7+F7-(C7+D7+G7)-E7 -> 8
A8: 2 | C8: 3 | G8: 1 | H8: =H7+B8+F8-(C8+D8+G8)-E8 -> 4
A9: 3 | B9: 3 | C9: 2 | H9: =H8+B9+F9-(C9+D9+G9)-E9 -> 5
A10: 4 | B10: 2 | C10: 1 | H10: =H9+B10+F10-(C10+D10+G10)-E10 -> 6
A11: 5 | B11: 2 | C11: 2 | H11: =H10+B11+F11-(C11+D11+G11)-E11 -> 6
A12: 6 | B12: 6 | C12: 1 | H12: =H11+B12+F12-(C12+D12+G12)-E12 -> 11
A13: 7 | B13: 2 | C13: 5 | H13: =H12+B13+F13-(C13+D13+G13)-E13 -> 8
A14: 8 | B14: 2 | H14: =H13+B14+F14-(C14+D14+G14)-E14 -> 10
A15: 9 | B15: 2 | C15: 3 | H15: =H14+B15+F15-(C15+D15+G15)-E15 -> 9
A16: 10 | B16: 2 | C16: 3 | G16: 1 | H16: =H15+B16+F16-(C16+D16+G16)-E16 -> 7
A17: 11 | C17: 2 | H17: =H16+B17+F17-(C17+D17+G17)-E17 -> 5
A18: 12 | B18: 2 | C18: 2 | H18: =H17+B18+F18-(C18+D18+G18)-E18 -> 5
A19: 13 | B19: 2 | C19: 2 | H19: =H18+B19+F19-(C19+D19+G19)-E19 -> 5
A20: 14 | B20: 3 | C20: 1 | H20: =H19+B20+F20-(C20+D20+G20)-E20 -> 7
A21: 15 | B21: 3 | C21: 3 | H21: =H20+B21+F21-(C21+D21+G21)-E21 -> 7
A22: 16 | B22: 2 | H22: =H21+B22+F22-(C22+D22+G22)-E22 -> 9
A23: 17 | B23: 5 | C23: 5 | H23: =H22+B23+F23-(C23+D23+G23)-E23 -> 9
A24: 18 | B24: 2 | C24: 2 | H24: =H23+B24+F24-(C24+D24+G24)-E24 -> 9
A25: 19 | B25: 3 | C25: 4 | H25: =H24+B25+F25-(C25+D25+G25)-E25 -> 8
A26: 20 | B26: 3 | C26: 2 | H26: =H25+B26+F26-(C26+D26+G26)-E26 -> 9
A27: 21 | B27: 3 | C27: 1 | H27: =H26+B27+F27-(C27+D27+G27)-E27 -> 11
A28: 22 | B28: 3 | C28: 3 | G28: 1 | H28: =H27+B28+F28-(C28+D28+G28)-E28 -> 10
A29: 23 | B29: 8 | C29: 1 | G29: 1 | H29: =H28+B29+F29-(C29+D29+G29)-E29 -> 16
A30: 24 | B30: 3 | C30: 5 | H30: =H29+B30+F30-(C30+D30+G30)-E30 -> 14
A31: 25 | B31: 1 | C31: 3 | G31: 1 | H31: =H30+B31+F31-(C31+D31+G31)-E31 -> 11
A32: 26 | B32: 4 | C32: 1 | H32: =H31+B32+F32-(C32+D32+G32)-E32 -> 14
A33: 27 | B33: 3 | C33: 7 | F33: 1 | H33: =H32+B33+F33-(C33+D33+G33)-E33 -> 11
A34: 28 | B34: 2 | C34: 2 | H34: =H33+B34+F34-(C34+D34+G34)-E34 -> 11
A35: 29 | B35: 5 | C35: 1 | H35: =H34+B35+F35-(C35+D35+G35)-E35 -> 15
A36: 30 | B36: 1 | C36: 6 | H36: =H35+B36+F36-(C36+D36+G36)-E36 -> 10
A37: 31 | B37: 2 | C37: 3 | G37: 2 | H37: =H36+B37+F37-(C37+D37+G37)-E37 -> 7
A38: TOTAL | B38: =SUM(B7:B37)-E38 -> 82 | C38: =SUM(C7:C37) -> 81 | D38: =SUM(D7:D37) -> 0 | E38: =SUM(E7:E37) -> 0 | F38: =SUM(F7:F37) -> 1 | G38: =SUM(G7:G37) -> 7 | H38: =SUM(H7:H37) -> 277
A41: GHANA HEALTH SERVICE
A42: DAILY BED UTILIZATION FORM
...

Sheet BLK G
A1: GHANA HEALTH SERVICE
A2: DAILY BED UTILIZATION FORM
A3: Hospital | B3: HOHOE MUNI HOSP | D3: Ward | E3: G | G3: MONTH | H3: JANUARY
A4: Number of patients remaining as at last day of previous month | H4: 8
A5: Bed complement | H5: 14
A6: Day of the Month | B6: Admissions | C6: Discharges | D6: Deaths | E6: Deaths <24Hrs | F6: Transfers-In | G6: Transfers-Out | H6: No. of Patients Remaning In Ward
A7: 1 | B7: 4 | C7: 5 | G7: 1 | H7: =H4+B7+F7-(C7+D7+G7)-E7 -> 6
A8: 2 | B8: 3 | C8: 1 | G8: 1 | H8: =H7+B8+F8-(C8+D8+G8)-E8 -> 7
A9: 3 | B9: 3 | C9: 1 | F9: 1 | H9: =H8+B9+F9-(C9+D9+G9)-E9 -> 10
A10: 4 | B10: 2 | C10: 9 | F10: 1 | G10: 2 | H10: =H9+B10+F10-(C10+D10+G10)-E10 -> 2
A11: 5 | B11: 3 | F11: 1 | G11: 1 | H11: =H10+B11+F11-(C11+D11+G11)-E11 -> 5
A12: 6 | B12: 5 | C12: 2 | G12: 1 | H12: =H11+B12+F12-(C12+D12+G12)-E12 -> 7
A13: 7 | B13: 3 | C13: 2 | F13: 2 | G13: 1 | H13: =H12+B13+F13-(C13+D13+G13)-E13 -> 9
A14: 8 | B14: 1 | C14: 4 | F14: 2 | H14: =H13+B14+F14-(C14+D14+G14)-E14 -> 8
A15: 9 | B15: 5 | C15: 5 | G15: 1 | H15: =H14+B15+F15-(C15+D15+G15)-E15 -> 7
A16: 10 | B16: 4 | C16: 3 | F16: 1 | H16: =H15+B16+F16-(C16+D16+G16)-E16 -> 9
A17: 11 | B17: 5 | C17: 4 | G17: 3 | H17: =H16+B17+F17-(C17+D17+G17)-E17 -> 7
A18: 12 | B18: 3 | C18: 4 | G18: 2 | H18: =H17+B18+F18-(C18+D18+G18)-E18 -> 4
A19: 13 | B19: 3 | C19: 2 | F19: 1 | H19: =H18+B19+F19-(C19+D19+G19)-E19 -> 6
A20: 14 | B20: 4 | C20: 5 | F20: 2 | G20: 2 | H20: =H19+B20+F20-(C20+D20+G20)-E20 -> 5
A21: 15 | B21: 5 | C21: 3 | G21: 1 | H21: =H20+B21+F21-(C21+D21+G21)-E21 -> 6
A22: 16 | B22: 3 | F22: 1 | H22: =H21+B22+F22-(C22+D22+G22)-E22 -> 10
A23: 17 | B23: 1 | C23: 8 | F23: 2 | G23: 1 | H23: =H22+B23+F23-(C23+D23+G23)-E23 -> 4
A24: 18 | B24: 2 | C24: 1 | H24: =H23+B24+F24-(C24+D24+G24)-E24 -> 5
A25: 19 | B25: 2 | C25: 2 | G25: 1 | H25: =H24+B25+F25-(C25+D25+G25)-E25 -> 4
A26: 20 | B26: 3 | C26: 3 | F26: 2 | H26: =H25+B26+F26-(C26+D26+G26)-E26 -> 6
A27: 21 | B27: 3 | C27: 1 | G27: 3 | H27: =H26+B27+F27-(C27+D27+G27)-E27 -> 5
A28: 22 | B28: 2 | C28: 1 | G28: 1 | H28: =H27+B28+F28-(C28+D28+G28)-E28 -> 5
A29: 23 | B29: 2 | H29: =H28+B29+F29-(C29+D29+G29)-E29 -> 7
A30: 24 | B30: 4 | C30: 4 | F30: 1 | G30: 1 | H30: =H29+B30+F30-(C30+D30+G30)-E30 -> 7
A31: 25 | B31: 2 | C31: 2 | F31: 1 | G31: 2 | H31: =H30+B31+F31-(C31+D31+G31)-E31 -> 6
A32: 26 | B32: 2 | C32: 2 | F32: 1 | H32: =H31+B32+F32-(C32+D32+G32)-E32 -> 7
A33: 27 | B33: 1 | C33: 3 | G33: 1 | H33: =H32+B33+F33-(C33+D33+G33)-E33 -> 4
A34: 28 | B34: 4 | H34: =H33+B34+F34-(C34+D34+G34)-E34 -> 8
A35: 29 | B35: 6 | C35: 1 | G35: 2 | H35: =H34+B35+F35-(C35+D35+G35)-E35 -> 11
A36: 30 | B36: 1 | C36: 9 | F36: 1 | H36: =H35+B36+F36-(C36+D36+G36)-E36 -> 4
A37: 31 | B37: 4 | C37: 3 | F37: 3 | H37: =H36+B37+F37-(C37+D37+G37)-E37 -> 8
A38: TOTAL | B38: =SUM(B7:B37)-E38 -> 95 | C38: =SUM(C7:C37) -> 90 | D38: =SUM(D7:D37) -> 0 | E38: =SUM(E7:E37) -> 0 | F38: =SUM(F7:F37) -> 23 | G38: =SUM(G7:G37) -> 28 | H38: =SUM(H7:H37) -> 199
A41: GHANA HEALTH SERVICE
A42: DAILY BED UTILIZATION FORM
...

Sheet BLK H
A1: GHANA HEALTH SERVICE
A2: DAILY BED UTILIZATION FORM
A3: Hospital | B3: HOHOE MUNI HOSP | D3: Ward | E3: BLK H | G3: MONTH | H3: JANUARY
A4: Number of patients remaining as at last day of previous month | H4: 12
A5: Bed complement | H5: 22
A6: Day of the Month | B6: Admissions | C6: Discharges | D6: Deaths | E6: Deaths <24Hrs | F6: Transfers-In | G6: Transfers-Out | H6: No. of Patients Remaning In Ward
A7: 1 | B7: 2 | C7: 2 | F7: 1 | H7: =H4+B7+F7-(C7+D7+G7)-E7 -> 13
A8: 2 | C8: 4 | F8: 2 | H8: =H7+B8+F8-(C8+D8+G8)-E8 -> 11
A9: 3 | B9: 5 | C9: 1 | G9: 1 | H9: =H8+B9+F9-(C9+D9+G9)-E9 -> 14
A10: 4 | C10: 1 | F10: 2 | G10: 1 | H10: =H9+B10+F10-(C10+D10+G10)-E10 -> 14
A11: 5 | B11: 2 | C11: 8 | F11: 1 | G11: 1 | H11: =H10+B11+F11-(C11+D11+G11)-E11 -> 8
A12: 6 | B12: 3 | C12: 2 | F12: 1 | H12: =H11+B12+F12-(C12+D12+G12)-E12 -> 10
A13: 7 | B13: 1 | C13: 3 | F13: 1 | G13: 2 | H13: =H12+B13+F13-(C13+D13+G13)-E13 -> 7
A14: 8 | B14: 3 | G14: 2 | H14: =H13+B14+F14-(C14+D14+G14)-E14 -> 8
A15: 9 | B15: 2 | F15: 1 | H15: =H14+B15+F15-(C15+D15+G15)-E15 -> 11
A16: 10 | C16: 4 | H16: =H15+B16+F16-(C16+D16+G16)-E16 -> 7
A17: 11 | B17: 1 | C17: 6 | F17: 3 | H17: =H16+B17+F17-(C17+D17+G17)-E17 -> 5
A18: 12 | C18: 1 | F18: 2 | H18: =H17+B18+F18-(C18+D18+G18)-E18 -> 6
A19: 13 | B19: 6 | C19: 4 | G19: 1 | H19: =H18+B19+F19-(C19+D19+G19)-E19 -> 7
A20: 14 | B20: 3 | F20: 2 | G20: 2 | H20: =H19+B20+F20-(C20+D20+G20)-E20 -> 10
A21: 15 | B21: 9 | C21: 1 | F21: 1 | H21: =H20+B21+F21-(C21+D21+G21)-E21 -> 19
A22: 16 | B22: 1 | C22: 3 | G22: 1 | H22: =H21+B22+F22-(C22+D22+G22)-E22 -> 16
A23: 17 | B23: 1 | C23: 2 | F23: 1 | G23: 2 | H23: =H22+B23+F23-(C23+D23+G23)-E23 -> 14
A24: 18 | B24: 1 | C24: 9 | H24: =H23+B24+F24-(C24+D24+G24)-E24 -> 6
A25: 19 | F25: 1 | H25: =H24+B25+F25-(C25+D25+G25)-E25 -> 7
A26: 20 | B26: 5 | C26: 1 | G26: 2 | H26: =H25+B26+F26-(C26+D26+G26)-E26 -> 9
A27: 21 | B27: 1 | C27: 1 | F27: 3 | H27: =H26+B27+F27-(C27+D27+G27)-E27 -> 12
A28: 22 | B28: 5 | C28: 1 | F28: 1 | H28: =H27+B28+F28-(C28+D28+G28)-E28 -> 17
A29: 23 | C29: 6 | F29: 1 | H29: =H28+B29+F29-(C29+D29+G29)-E29 -> 12
A30: 24 | B30: 3 | C30: 1 | F30: 1 | G30: 1 | H30: =H29+B30+F30-(C30+D30+G30)-E30 -> 14
A31: 25 | B31: 2 | C31: 3 | F31: 3 | G31: 1 | H31: =H30+B31+F31-(C31+D31+G31)-E31 -> 15
A32: 26 | B32: 1 | C32: 3 | G32: 1 | H32: =H31+B32+F32-(C32+D32+G32)-E32 -> 12
A33: 27 | B33: 3 | C33: 3 | F33: 1 | H33: =H32+B33+F33-(C33+D33+G33)-E33 -> 13
A34: 28 | B34: 2 | C34: 2 | H34: =H33+B34+F34-(C34+D34+G34)-E34 -> 13
A35: 29 | B35: 3 | F35: 2 | H35: =H34+B35+F35-(C35+D35+G35)-E35 -> 18
A36: 30 | B36: 3 | C36: 2 | G36: 1 | H36: =H35+B36+F36-(C36+D36+G36)-E36 -> 18
A37: 31 | B37: 1 | C37: 3 | G37: 1 | H37: =H36+B37+F37-(C37+D37+G37)-E37 -> 15
A38: TOTAL | B38: =SUM(B7:B37)-E38 -> 69 | C38: =SUM(C7:C37) -> 77 | D38: =SUM(D7:D37) -> 0 | E38: =SUM(E7:E37) -> 0 | F38: =SUM(F7:F37) -> 31 | G38: =SUM(G7:G37) -> 20 | H38: =SUM(H7:H37) -> 361
A41: GHANA HEALTH SERVICE
A42: DAILY BED UTILIZATION FORM
...

Sheet Neonatal
A1: GHANA HEALTH SERVICE
A2: DAILY BED UTILIZATION FORM
A3: Hospital | B3: HOHOE MUNI HOSP | D3: Ward | E3: NEONATAL | G3: MONTH | H3: JANUARY
A4: Number of patients remaining as at last day of previous month | H4: 11
A5: Bed complement | H5: 15
A6: Day of the Month | B6: Admissions | C6: Discharges | D6: Deaths | E6: Deaths <24Hrs | F6: Transfers-In | G6: Transfers-Out | H6: No. of Patients Remaning In Ward
A7: 1 | B7: 2 | C7: 3 | H7: =H4+B7+F7-(C7+D7+G7)-E7 -> 10
A8: 2 | B8: 1 | H8: =H7+B8+F8-(C8+D8+G8)-E8 -> 11
A9: 3 | B9: 2 | C9: 2 | H9: =H8+B9+F9-(C9+D9+G9)-E9 -> 11
A10: 4 | B10: 1 | C10: 3 | H10: =H9+B10+F10-(C10+D10+G10)-E10 -> 9
A11: 5 | B11: 1 | C11: 1 | H11: =H10+B11+F11-(C11+D11+G11)-E11 -> 9
A12: 6 | B12: 1 | C12: 4 | H12: =H11+B12+F12-(C12+D12+G12)-E12 -> 6
A13: 7 | B13: 1 | H13: =H12+B13+F13-(C13+D13+G13)-E13 -> 7
A14: 8 | C14: 1 | H14: =H13+B14+F14-(C14+D14+G14)-E14 -> 6
A15: 9 | B15: 2 | C15: 1 | H15: =H14+B15+F15-(C15+D15+G15)-E15 -> 7
A16: 10 | C16: 1 | H16: =H15+B16+F16-(C16+D16+G16)-E16 -> 6
A17: 11 | B17: 1 | C17: 2 | H17: =H16+B17+F17-(C17+D17+G17)-E17 -> 5
A18: 12 | B18: 3 | H18: =H17+B18+F18-(C18+D18+G18)-E18 -> 8
A19: 13 | B19: 1 | H19: =H18+B19+F19-(C19+D19+G19)-E19 -> 9
A20: 14 | B20: 3 | H20: =H19+B20+F20-(C20+D20+G20)-E20 -> 12
A21: 15 | B21: 1 | C21: 2 | H21: =H20+B21+F21-(C21+D21+G21)-E21 -> 11
A22: 16 | B22: 1 | H22: =H21+B22+F22-(C22+D22+G22)-E22 -> 12
A23: 17 | B23: 2 | D23: 1 | H23: =H22+B23+F23-(C23+D23+G23)-E23 -> 13
A24: 18 | C24: 1 | H24: =H23+B24+F24-(C24+D24+G24)-E24 -> 12
A25: 19 | B25: 2 | C25: 2 | H25: =H24+B25+F25-(C25+D25+G25)-E25 -> 12
A26: 20 | B26: 1 | C26: 1 | H26: =H25+B26+F26-(C26+D26+G26)-E26 -> 12
A27: 21 | B27: 2 | C27: 1 | H27: =H26+B27+F27-(C27+D27+G27)-E27 -> 13
A28: 22 | B28: 5 | C28: 2 | H28: =H27+B28+F28-(C28+D28+G28)-E28 -> 16
A29: 23 | C29: 2 | H29: =H28+B29+F29-(C29+D29+G29)-E29 -> 14
A30: 24 | B30: 2 | C30: 1 | G30: 1 | H30: =H29+B30+F30-(C30+D30+G30)-E30 -> 14
A31: 25 | C31: 2 | H31: =H30+B31+F31-(C31+D31+G31)-E31 -> 12
A32: 26 | C32: 2 | H32: =H31+B32+F32-(C32+D32+G32)-E32 -> 10
A33: 27 | B33: 1 | C33: 3 | H33: =H32+B33+F33-(C33+D33+G33)-E33 -> 8
A34: 28 | B34: 1 | H34: =H33+B34+F34-(C34+D34+G34)-E34 -> 9
A35: 29 | B35: 3 | C35: 2 | H35: =H34+B35+F35-(C35+D35+G35)-E35 -> 10
A36: 30 | B36: 2 | C36: 1 | H36: =H35+B36+F36-(C36+D36+G36)-E36 -> 11
A37: 31 | B37: 2 | C37: 2 | H37: =H36+B37+F37-(C37+D37+G37)-E37 -> 11
A38: TOTAL | B38: =SUM(B7:B37)-E38 -> 44 | C38: =SUM(C7:C37) -> 42 | D38: =SUM(D7:D37) -> 1 | E38: =SUM(E7:E37) -> 0 | F38: =SUM(F7:F37) -> 0 | G38: =SUM(G7:G37) -> 1 | H38: =SUM(H7:H37) -> 316
A41: GHANA HEALTH SERVICE
A42: DAILY BED UTILIZATION FORM
...

Sheet Male Emergency
A1: GHANA HEALTH SERVICE
A2: DAILY BED UTILIZATION FORM
A3: Hospital | B3: HOHOE MUNI HOSP | D3: Ward | E3: MALE EMERGENCY | G3: MONTH | H3: JANUARY
A4: Number of patients remaining as at last day of previous month | H4: 2
A5: Bed complement | H5: 10
A6: Day of the Month | B6: Admissions | C6: Discharges | D6: Deaths | E6: Deaths <24Hrs | F6: Transfers-In | G6: Transfers-Out | H6: No. of Patients Remaning In Ward
A7: 1 | B7: 3 | C7: 1 | G7: 1 | H7: =H4+B7+F7-(C7+D7+G7)-E7 -> 3
A8: 2 | B8: 3 | C8: 1 | D8: 1 | G8: 1 | H8: =H7+B8+F8-(C8+D8+G8)-E8 -> 3
A9: 3 | B9: 4 | G9: 1 | H9: =H8+B9+F9-(C9+D9+G9)-E9 -> 6
A10: 4 | B10: 2 | C10: 1 | D10: 1 | G10: 1 | H10: =H9+B10+F10-(C10+D10+G10)-E10 -> 5
A11: 5 | H11: =H10+B11+F11-(C11+D11+G11)-E11 -> 5
A12: 6 | B12: 2 | C12: 2 | G12: 1 | H12: =H11+B12+F12-(C12+D12+G12)-E12 -> 4
A13: 7 | G13: 1 | H13: =H12+B13+F13-(C13+D13+G13)-E13 -> 3
A14: 8 | B14: 4 | C14: 2 | G14: 1 | H14: =H13+B14+F14-(C14+D14+G14)-E14 -> 4
A15: 9 | B15: 2 | G15: 1 | H15: =H14+B15+F15-(C15+D15+G15)-E15 -> 5
A16: 10 | B16: 1 | D16: 1 | G16: 1 | H16: =H15+B16+F16-(C16+D16+G16)-E16 -> 4
A17: 11 | B17: 3 | E17: 1 | G17: 1 | H17: =H16+B17+F17-(C17+D17+G17)-E17 -> 5
A18: 12 | B18: 1 | G18: 2 | H18: =H17+B18+F18-(C18+D18+G18)-E18 -> 4
A19: 13 | B19: 1 | C19: 1 | D19: 1 | G19: 1 | H19: =H18+B19+F19-(C19+D19+G19)-E19 -> 2
A20: 14 | G20: 1 | H20: =H19+B20+F20-(C20+D20+G20)-E20 -> 1
A21: 15 | B21: 1 | C21: 1 | H21: =H20+B21+F21-(C21+D21+G21)-E21 -> 1
A22: 16 | B22: 4 | G22: 1 | H22: =H21+B22+F22-(C22+D22+G22)-E22 -> 4
A23: 17 | B23: 3 | C23: 1 | G23: 1 | H23: =H22+B23+F23-(C23+D23+G23)-E23 -> 5
A24: 18 | B24: 2 | C24: 1 | H24: =H23+B24+F24-(C24+D24+G24)-E24 -> 6
A25: 19 | B25: 6 | C25: 2 | D25: 1 | E25: 3 | G25: 1 | H25: =H24+B25+F25-(C25+D25+G25)-E25 -> 5
A26: 20 | B26: 3 | C26: 1 | G26: 3 | H26: =H25+B26+F26-(C26+D26+G26)-E26 -> 4
A27: 21 | B27: 1 | C27: 2 | E27: 1 | G27: 1 | H27: =H26+B27+F27-(C27+D27+G27)-E27 -> 1
A28: 22 | B28: 5 | C28: 1 | H28: =H27+B28+F28-(C28+D28+G28)-E28 -> 5
A29: 23 | B29: 3 | H29: =H28+B29+F29-(C29+D29+G29)-E29 -> 8
A30: 24 | B30: 2 | C30: 2 | G30: 1 | H30: =H29+B30+F30-(C30+D30+G30)-E30 -> 7
A31: 25 | B31: 1 | C31: 6 | E31: 1 | H31: =H30+B31+F31-(C31+D31+G31)-E31 -> 1
A32: 26 | G32: 1 | H32: =H31+B32+F32-(C32+D32+G32)-E32 -> 0
A33: 27 | B33: 5 | E33: 1 | H33: =H32+B33+F33-(C33+D33+G33)-E33 -> 4
A34: 28 | B34: 5 | H34: =H33+B34+F34-(C34+D34+G34)-E34 -> 9
A35: 29 | B35: 1 | C35: 2 | D35: 1 | G35: 1 | H35: =H34+B35+F35-(C35+D35+G35)-E35 -> 6
A36: 30 | B36: 1 | C36: 3 | G36: 2 | H36: =H35+B36+F36-(C36+D36+G36)-E36 -> 2
A37: 31 | B37: 1 | C37: 1 | G37: 1 | H37: =H36+B37+F37-(C37+D37+G37)-E37 -> 1
A38: TOTAL | B38: =SUM(B7:B37)-E38 -> 63 | C38: =SUM(C7:C37) -> 31 | D38: =SUM(D7:D37) -> 6 | E38: =SUM(E7:E37) -> 7 | F38: =SUM(F7:F37) -> 0 | G38: =SUM(G7:G37) -> 27 | H38: =SUM(H7:H37) -> 123
A41: GHANA HEALTH SERVICE
A42: DAILY BED UTILIZATION FORM
...

Sheet Female Emergency
A1: GHANA HEALTH SERVICE
A2: DAILY BED UTILIZATION FORM
A3: Hospital | B3: HOHOE MUNI HOSP | D3: Ward | G3: MONTH | H3: JANUARY
A4: Number of patients remaining as at last day of previous month | H4: 4
A5: Bed complement | H5: 10
A6: Day of the Month | B6: Admissions | C6: Discharges | D6: Deaths | E6: Deaths <24Hrs | F6: Transfers-In | G6: Transfers-Out | H6: No. of Patients Remaning In Ward | I6: No. of Patients Remaning In Ward
A7: 1 | B7: 2 | C7: 1 | H7: =H4+B7+F7-(C7+D7+G7)-E7 -> 5 | I7: ='Male Emergency'!H7+H7 -> 8
A8: 2 | B8: 1 | G8: 3 | H8: =H7+B8+F8-(C8+D8+G8)-E8 -> 3 | I8: ='Male Emergency'!H8+H8 -> 6
A9: 3 | B9: 2 | C9: 1 | D9: 1 | G9: 1 | H9: =H8+B9+F9-(C9+D9+G9)-E9 -> 2 | I9: ='Male Emergency'!H9+H9 -> 8
A10: 4 | B10: 2 | G10: 2 | H10: =H9+B10+F10-(C10+D10+G10)-E10 -> 2 | I10: ='Male Emergency'!H10+H10 -> 7
A11: 5 | B11: 2 | H11: =H10+B11+F11-(C11+D11+G11)-E11 -> 4 | I11: ='Male Emergency'!H11+H11 -> 9
A12: 6 | B12: 1 | C12: 2 | H12: =H11+B12+F12-(C12+D12+G12)-E12 -> 3 | I12: ='Male Emergency'!H12+H12 -> 7
A13: 7 | G13: 2 | H13: =H12+B13+F13-(C13+D13+G13)-E13 -> 1 | I13: ='Male Emergency'!H13+H13 -> 4
A14: 8 | B14: 2 | H14: =H13+B14+F14-(C14+D14+G14)-E14 -> 3 | I14: ='Male Emergency'!H14+H14 -> 7
A15: 9 | B15: 2 | G15: 3 | H15: =H14+B15+F15-(C15+D15+G15)-E15 -> 2 | I15: ='Male Emergency'!H15+H15 -> 7
A16: 10 | B16: 1 | G16: 1 | H16: =H15+B16+F16-(C16+D16+G16)-E16 -> 2 | I16: ='Male Emergency'!H16+H16 -> 6
A17: 11 | H17: =H16+B17+F17-(C17+D17+G17)-E17 -> 2 | I17: ='Male Emergency'!H17+H17 -> 7
A18: 12 | B18: 3 | G18: 1 | H18: =H17+B18+F18-(C18+D18+G18)-E18 -> 4 | I18: ='Male Emergency'!H18+H18 -> 8
A19: 13 | B19: 1 | C19: 1 | G19: 2 | H19: =H18+B19+F19-(C19+D19+G19)-E19 -> 2 | I19: ='Male Emergency'!H19+H19 -> 4
A20: 14 | B20: 2 | H20: =H19+B20+F20-(C20+D20+G20)-E20 -> 4 | I20: ='Male Emergency'!H20+H20 -> 5
A21: 15 | B21: 5 | D21: 1 | G21: 2 | H21: =H20+B21+F21-(C21+D21+G21)-E21 -> 6 | I21: ='Male Emergency'!H21+H21 -> 7
A22: 16 | B22: 4 | C22: 2 | G22: 3 | H22: =H21+B22+F22-(C22+D22+G22)-E22 -> 5 | I22: ='Male Emergency'!H22+H22 -> 9
A23: 17 | B23: 1 | G23: 1 | H23: =H22+B23+F23-(C23+D23+G23)-E23 -> 5 | I23: ='Male Emergency'!H23+H23 -> 10
A24: 18 | D24: 1 | H24: =H23+B24+F24-(C24+D24+G24)-E24 -> 4 | I24: ='Male Emergency'!H24+H24 -> 10
A25: 19 | B25: 2 | G25: 2 | H25: =H24+B25+F25-(C25+D25+G25)-E25 -> 4 | I25: ='Male Emergency'!H25+H25 -> 9
A26: 20 | B26: 1 | G26: 2 | H26: =H25+B26+F26-(C26+D26+G26)-E26 -> 3 | I26: ='Male Emergency'!H26+H26 -> 7
A27: 21 | C27: 1 | G27: 1 | H27: =H26+B27+F27-(C27+D27+G27)-E27 -> 1 | I27: ='Male Emergency'!H27+H27 -> 2
A28: 22 | B28: 3 | G28: 2 | H28: =H27+B28+F28-(C28+D28+G28)-E28 -> 2 | I28: ='Male Emergency'!H28+H28 -> 7
A29: 23 | B29: 1 | H29: =H28+B29+F29-(C29+D29+G29)-E29 -> 3 | I29: ='Male Emergency'!H29+H29 -> 11
A30: 24 | B30: 1 | G30: 1 | H30: =H29+B30+F30-(C30+D30+G30)-E30 -> 3 | I30: ='Male Emergency'!H30+H30 -> 10
A31: 25 | H31: =H30+B31+F31-(C31+D31+G31)-E31 -> 3 | I31: ='Male Emergency'!H31+H31 -> 4
A32: 26 | B32: 2 | C32: 1 | H32: =H31+B32+F32-(C32+D32+G32)-E32 -> 4 | I32: ='Male Emergency'!H32+H32 -> 4
A33: 27 | B33: 1 | D33: 1 | G33: 1 | H33: =H32+B33+F33-(C33+D33+G33)-E33 -> 3 | I33: ='Male Emergency'!H33+H33 -> 7
A34: 28 | B34: 1 | G34: 2 | H34: =H33+B34+F34-(C34+D34+G34)-E34 -> 2 | I34: ='Male Emergency'!H34+H34 -> 11
A35: 29 | B35: 1 | G35: 1 | H35: =H34+B35+F35-(C35+D35+G35)-E35 -> 2 | I35: ='Male Emergency'!H35+H35 -> 8
A36: 30 | B36: 2 | H36: =H35+B36+F36-(C36+D36+G36)-E36 -> 4 | I36: ='Male Emergency'!H36+H36 -> 6
A37: 31 | E37: 1 | H37: =H36+B37+F37-(C37+D37+G37)-E37 -> 3 | I37: ='Male Emergency'!H37+H37 -> 4
A38: TOTAL | B38: =SUM(B7:B37)-E38 -> 45 | C38: =SUM(C7:C37) -> 9 | D38: =SUM(D7:D37) -> 4 | E38: =SUM(E7:E37) -> 1 | F38: =SUM(F7:F37) -> 0 | G38: =SUM(G7:G37) -> 33 | H38: =SUM(H7:H37) -> 96 | I38: ='Male Emergency'!H38+H38 -> 219
A41: GHANA HEALTH SERVICE
A42: DAILY BED UTILIZATION FORM
...

Sheet AGE_VT
F1: 44166
A2: AGE | B2: SEX | C2: WARD | F2: AGE | G2: SEX | H2: WARD
A3: 19 | B3: M | C3: M/W | F3: 49 | G3: M | H3: M/W
A4: 49 | B4: M | C4: M/W | F4: 60 | G4: M | H4: M/W
A5: 52 | B5: M | C5: M/W | F5: 67 | G5: M | H5: M/W
A6: 84 | B6: M | C6: M/W | F6: 26 | G6: M | H6: M/W
A7: 42 | B7: M | C7: M/W | F7: 55 | G7: M | H7: M/W
A8: 66 | B8: M | C8: M/W | F8: 38 | G8: M | H8: M/W
A9: 62 | B9: M | C9: M/W | F9: 25 | G9: M | H9: M/W
A10: 30 | B10: M | C10: M/W | F10: 62 | G10: M | H10: M/W
A11: 37 | B11: M | C11: M/W | F11: 64 | G11: M | H11: M/W
A12: 22 | B12: M | C12: M/W | F12: 57 | G12: M | H12: M/W
A13: 39 | B13: M | C13: M/W | F13: 70 | G13: M | H13: M/W
A14: 17 | B14: M | C14: M/W | F14: 24 | G14: M | H14: M/W
... A90: 22 | B90: F | C90: F/W | F90: 65 | G90: M | H90: M/W
A91: 56 | B91: F | C91: F/W | F91: 23 | G91: F | H91: F/W | L91: 31 | M91: 30
A92: 30 | B92: F | C92: F/W | F92: 62 | G92: F | H92: F/W | L92: 8 | M92: 4
A93: 20 | B93: F | C93: F/W | F93: 67 | G93: F | H93: F/W | L93: 31 | M93: 28
A94: 42 | B94: F | C94: F/W | F94: 24 | G94: F | H94: F/W | L94: 17 | M94: 15
A95: 55 | B95: F | C95: F/W | F95: 56 | G95: F | H95: F/W | L95: 14 | M95: 19
A96: 46 | B96: F | C96: F/W | F96: 79 | G96: F | H96: F/W | L96: 17 | M96: 7
A97: 20 | B97: F | C97: F/W | F97: 84 | G97: F | H97: F/W | L97: 35 | M97: 8
A98: 80 | B98: F | C98: F/W | F98: 67 | G98: F | H98: F/W | L98: 233 | M98: 56
A99: 74 | B99: F | C99: F/W | F99: 68 | G99: F | H99: F/W | L99: 76 | M99: 46
A100: 24 | B100: F | C100: F/W | F100: 18 | G100: F | H100: F/W | L100: 23 | M100: 25
A101: 56 | B101: F | C101: F/W | F101: 77 | G101: F | H101: F/W | L101: 26 | M101: 31
A102: 25 | B102: F | C102: F/W | F102: 84 | G102: F | H102: F/W | L102: 27 | M102: 22
A103: 17 | B103: F | C103: F/W | F103: 47 | G103: F | H103: F/W | L103: =SUBTOTAL(9,L91:L102) -> 538 | M103: =SUBTOTAL(9,M91:M102) -> 291
A104: 48 | B104: F | C104: F/W | F104: 53 | G104: F | H104: F/W
A105: 16 | B105: F | C105: F/W | F105: 34 | G105: F | H105: F/W
A106: 84 | B106: F | C106: F/W | F106: 68 | G106: F | H106: F/W
A107: 92 | B107: F | C107: F/W | F107: 18 | G107: F | H107: F/W
A108: 62 | B108: F | C108: F/W | F108: 88 | G108: F | H108: F/W
A109: 23 | B109: F | C109: F/W | F109: 53 | G109: F | H109: F/W
A110: 41 | B110: F | C110: F/W | F110: 18 | G110: F | H110: F/W
A111: 22 | B111: F | C111: F/W | F111: 47 | G111: F | H111: F/W
A112: 70 | B112: F | C112: F/W | F112: 22 | G112: F | H112: F/W
A113: 56 | B113: F | C113: F/W | F113: 38 | G113: F | H113: F/W
A114: 49 | B114: F | C114: F/W | F114: 47 | G114: F | H114: F/W
A115: 79 | B115: F | C115: F/W | F115: 17 | G115: F | H115: F/W
...

Sheet Ages
A1: 2025 | B1: JAN | E1: 2025 | F1: FEB | I1: 2025 | J1: MARCH | M1: 2025 | N1: APRIL | Q1: 2025 | R1: MAY | U1: 2025 | V1: JUNE | Y1: 2025 JULY | AC1: 2025 | AD1: AUGUST | AG1: 2025 | AH1: SEPTEMBER | AK1: 2025 | AL1: OCTOBER | AO1: 45962 | AS1: 45992
A2: Age | B2: Sex | C2: ward | E2: Age | F2: Sex | G2: Ward | I2: Age | J2: Sex | K2: Ward | M2: Age | N2: Sex | O2: Ward | Q2: Age | R2: Sex | S2: Ward | U2: Age | V2: Sex | W2: Ward | Y2: AGE | Z2: SEX | AA2: WARD | AC2: AGE | AD2: SEX | AE2: WARD | AG2: AGE | AH2: SEX | AI2: WARD | AK2: Age | AL2: Sex | AM2: Ward | AO2: Age | AP2: Sex | AQ2: Ward | AS2: Age | AT2: Sex | AU2: Ward
A3: 2 | B3: M | C3: A/E | E3: 9 MTHS | F3: M | G3: C/W | I3: 50 | J3: F | K3: A/E | M3: 74 | N3: M | O3: M/W | Q3: 41 | R3: M | S3: M/W | U3: 36 | V3: M | W3: A/E | Y3: 13 | Z3: M | AA3: M/W | AC3: 18 | AD3: M | AE3: M/W | AG3: 72 | AH3: M | AI3: M/W | AK3: 67 | AL3: m | AM3: m/w | AO3: 18 | AP3: m | AQ3: M/W
A4: 2 | B4: M | C4: A/E | E4: 9 MTHS | F4: M | G4: C/W | I4: 3 | J4: M | K4: A/E | M4: 17 | N4: M | O4: M/W | Q4: 20 | R4: M | S4: M/W | U4: 7 | V4: F | W4: A/E | Y4: 50 | Z4: M | AA4: M/W | AC4: 74 | AD4: M | AE4: M/W | AG4: 16 | AH4: M | AI4: M/W | AK4: 61 | AL4: m | AM4: m/w | AO4: 22 | AP4: m | AQ4: M/W
A5: 3 | B5: M | C5: A/E | E5: 8 MTHS | F5: F | G5: C/W | I5: 23 | J5: M | K5: A/E | M5: 65 | N5: M | O5: M/W | Q5: 16 | R5: M | S5: M/W | U5: 64 | V5: F | W5: A/E | Y5: 62 | Z5: M | AA5: M/W | AC5: 20 | AD5: M | AE5: M/W | AG5: 16 | AH5: M | AI5: M/W | AK5: 83 | AL5: m | AM5: m/w | AO5: 18 | AP5: m | AQ5: M/W
A6: 15 | B6: F | C6: A/E | E6: 8 MTHS | F6: M | G6: C/W | I6: 17 | J6: F | K6: A/E | M6: 61 | N6: M | O6: M/W | Q6: 16 | R6: M | S6: M/W | U6: 29 | V6: M | W6: A/E | Y6: 40 | Z6: M | AA6: M/W | AC6: 30 | AD6: M | AE6: M/W | AG6: 37 | AH6: M | AI6: M/W | AK6: 74 | AL6: m | AM6: m/w | AO6: 48 | AP6: m | AQ6: M/W
A7: 19 | B7: F | C7: A/E | E7: 8 D | F7: M | G7: NICU | I7: 44 | J7: M | K7: A/E | M7: 57 | N7: M | O7: M/W | Q7: 49 | R7: M | S7: M/W | U7: 65 | V7: M | W7: A/E | Y7: 70 | Z7: M | AA7: M/W | AC7: 19 | AD7: M | AE7: M/W | AG7: 17 | AH7: M | AI7: M/W | AK7: 17 | AL7: m | AM7: m/w | AO7: 95 | AP7: m | AQ7: M/W
A8: 20 | B8: F | C8: A/E | E8: 8 D | F8: F | G8: NICU | I8: 69 | J8: F | K8: A/E | M8: 25 | N8: M | O8: M/W | Q8: 39 | R8: M | S8: M/W | U8: 10 | V8: F | W8: A/E | Y8: 17 | Z8: M | AA8: M/W | AC8: 18 | AD8: M | AE8: M/W | AG8: 50 | AH8: M | AI8: M/W | AK8: 70 | AL8: m | AM8: m/w | AO8: 62 | AP8: m | AQ8: M/W
A9: 3 | B9: M | C9: A/E | E9: 8 D | F9: F | G9: NICU | I9: 2 | J9: F | K9: A/E | M9: 73 | N9: M | O9: M/W | Q9: 18 | R9: M | S9: M/W | U9: 39 | V9: F | W9: A/E | Y9: 16 | Z9: M | AA9: M/W | AC9: 15 | AD9: M | AE9: M/W | AG9: 54 | AH9: M | AI9: M/W | AK9: 73 | AL9: m | AM9: m/w | AO9: 20 | AP9: m | AQ9: M/W
A10: 4 | B10: M | C10: A/E | E10: 7 D | F10: M | G10: NICU | I10: 23 | J10: M | K10: A/E | M10: 92 | N10: M | O10: M/W | Q10: 40 | R10: M | S10: M/W | U10: 65 | V10: M | W10: A/E | Y10: 48 | Z10: M | AA10: M/W | AC10: 19 | AD10: M | AE10: M/W | AG10: 34 | AH10: M | AI10: M/W | AK10: 62 | AL10: m | AM10: m/w | AO10: 56 | AP10: m | AQ10: M/W
A11: 7 | B11: M | C11: A/E | E11: 7 D | F11: M | G11: NICU | I11: 42 | J11: F | K11: A/E | M11: 30 | N11: M | O11: M/W | Q11: 30 | R11: M | S11: M/W | U11: 61 | V11: F | W11: A/E | Y11: 83 | Z11: M | AA11: M/W | AC11: 74 | AD11: M | AE11: M/W | AG11: 33 | AH11: M | AI11: M/W | AK11: 40 | AL11: m | AM11: m/w | AO11: 54 | AP11: m | AQ11: M/W
A12: 13 | B12: M | C12: A/E | E12: 7 D | F12: M | G12: NICU | I12: 19 | J12: M | K12: A/E | M12: 58 | N12: M | O12: M/W | Q12: 62 | R12: M | S12: M/W | U12: 41 | V12: M | W12: A/E | Y12: 49 | Z12: M | AA12: M/W | AC12: 24 | AD12: M | AE12: M/W | AG12: 13 | AH12: M | AI12: M/W | AK12: 23 | AL12: m | AM12: m/w | AO12: 49 | AP12: m | AQ12: M/W
A13: 21 | B13: F | C13: A/E | E13: 6 MTHS | F13: M | G13: C/W | I13: 56 | J13: M | K13: A/E | M13: 77 | N13: M | O13: M/W | Q13: 37 | R13: M | S13: M/W | U13: 31 | V13: M | W13: A/E | Y13: 79 | Z13: M | AA13: M/W | AC13: 17 | AD13: M | AE13: M/W | AG13: 78 | AH13: M | AI13: M/W | AK13: 42 | AL13: m | AM13: m/w | AO13: 55 | AP13: m | AQ13: M/W
A14: 23 | B14: F | C14: A/E | E14: 6 MTHS | F14: M | G14: C/W | I14: 31 | J14: M | K14: A/E | M14: 74 | N14: M | O14: M/W | Q14: 62 | R14: M | S14: M/W | U14: 55 | V14: M | W14: A/E | Y14: 60 | Z14: M | AA14: M/W | AC14: 88 | AD14: M | AE14: M/W | AG14: 51 | AH14: M | AI14: M/W | AK14: 23 | AL14: m | AM14: m/w | AO14: 83 | AP14: m | AQ14: M/W
... A79: 65 | B79: F | C79: A/E | E79: 0 D | F79: M | G79: NICU | I79: 76 | J79: F | K79: A/E | M79: 26 | N79: F | O79: F/W | Q79: 70 | R79: F | S79: F/W | U79: 47 | V79: F | W79: BLK F | Y79: 33 | Z79: F | AA79: F/W | AC79: 67 | AD79: M | AE79: M/W | AG79: 12 | AH79: M | AI79: C/W | AK79: 31 | AL79: f | AM79: f/w | AO79: 21 | AP79: f | AQ79: F/W
A80: 66 | B80: F | C80: A/E | E80: 0 D | F80: F | G80: NICU | I80: 19 | J80: M | K80: A/E | M80: 21 | N80: F | O80: F/W | Q80: 50 | R80: F | S80: F/W | U80: 28 | V80: F | W80: BLK F | Y80: 51 | Z80: F | AA80: F/W | AC80: 71 | AD80: M | AE80: M/W | AG80: 7 MTH | AH80: M | AI80: C/W | AK80: 54 | AL80: f | AM80: f/w | AO80: 31 | AP80: f | AQ80: F/W
A81: 60 | B81: M | C81: A/E | E81: 0 D | F81: F | G81: NICU | I81: 18 | J81: F | K81: A/E | M81: 23 | N81: F | O81: F/W | Q81: 52 | R81: F | S81: F/W | U81: 27 | V81: F | W81: BLK F | Y81: 58 | Z81: F | AA81: F/W | AC81: 41 | AD81: M | AE81: M/W | AG81: 4 | AH81: M | AI81: C/W | AK81: 74 | AL81: f | AM81: f/w | AO81: 15 | AP81: f | AQ81: F/W
A82: 67 | B82: F | C82: A/E | E82: 0 D | F82: F | G82: NICU | I82: 59 | J82: F | K82: A/E | M82: 96 | N82: F | O82: F/W | Q82: 51 | R82: F | S82: F/W | U82: 40 | V82: F | W82: BLK F | Y82: 47 | Z82: F | AA82: F/W | AC82: 25 | AD82: M | AE82: M/W | AG82: 4 | AH82: F | AI82: C/W | AK82: 20 | AL82: f | AM82: f/w | AO82: 62 | AP82: f | AQ82: F/W
A83: 60 | B83: M | C83: A/E | E83: 0 D | F83: M | G83: NICU | I83: 69 | J83: M | K83: A/E | M83: 54 | N83: F | O83: F/W | Q83: 36 | R83: F | S83: F/W | U83: 30 | V83: F | W83: BLK F | Y83: 16 | Z83: F | AA83: F/W | AC83: 18 | AD83: M | AE83: M/W | AG83: 7 | AH83: M | AI83: C/W | AK83: 85 | AL83: f | AM83: f/w | AO83: 16 | AP83: f | AQ83: F/W
A84: 62 | B84: M | C84: A/E | E84: 98 | F84: M | G84: A/E | I84: 56 | J84: F | K84: A/E | M84: 25 | N84: F | O84: F/W | Q84: 72 | R84: F | S84: F/W | U84: 34 | V84: F | W84: BLK F | Y84: 86 | Z84: F | AA84: F/W | AC84: 61 | AD84: M | AE84: M/W | AG84: 10 MTH | AH84: M | AI84: C/W | AK84: 79 | AL84: f | AM84: f/w | AO84: 37 | AP84: f | AQ84: F/W
A85: 71 | B85: F | C85: A/E | E85: 92 | F85: M | G85: M/W | I85: 42 | J85: F | K85: A/E | M85: 5 | N85: F | O85: C/W | Q85: 51 | R85: F | S85: F/W | U85: 29 | V85: F | W85: BLK F | Y85: 62 | Z85: F | AA85: F/W | AC85: 13 | AD85: M | AE85: M/W | AG85: 6 | AH85: F | AI85: C/W | AK85: 13 | AL85: f | AM85: f/w | AO85: 22 | AP85: f | AQ85: F/W
A86: 63 | B86: M | C86: A/E | E86: 90 | F86: M | G86: A/E | I86: 61 | J86: F | K86: A/E | M86: 4 | N86: M | O86: C/W | Q86: 17 | R86: F | S86: F/W | U86: 34 | V86: F | W86: BLK F | Y86: 68 | Z86: F | AA86: F/W | AC86: 91 | AD86: M | AE86: M/W | AG86: 10 | AH86: F | AI86: C/W | AK86: 55 | AL86: f | AM86: f/w | AO86: 26 | AP86: f | AQ86: F/W
A87: 64 | B87: M | C87: A/E | E87: 89 | F87: M | G87: A/E | I87: 63 | J87: M | K87: A/E | M87: 1 | N87: F | O87: C/W | Q87: 50 | R87: F | S87: F/W | U87: 30 | V87: F | W87: BLK F | Y87: 43 | Z87: F | AA87: F/W | AC87: 56 | AD87: M | AE87: M/W | AG87: 2 | AH87: F | AI87: C/W | AK87: 81 | AL87: f | AM87: f/w | AO87: 49 | AP87: f | AQ87: F/W
A88: 65 | B88: M | C88: A/E | E88: 89 | F88: M | G88: M/W | I88: 57 | J88: F | K88: A/E | M88: 10 | N88: M | O88: C/W | Q88: 16 | R88: F | S88: F/W | U88: 33 | V88: F | W88: BLK F | Y88: 27 | Z88: F | AA88: F/W | AC88: 19 | AD88: M | AE88: M/W | AG88: 3 | AH88: F | AI88: C/W | AK88: 62 | AL88: f | AM88: f/w | AO88: 70 | AP88: f | AQ88: F/W
A89: 71 | B89: F | C89: A/E | E89: 88 | F89: M | G89: A/E | I89: 75 | J89: M | K89: A/E | M89: 5 | N89: M | O89: C/W | Q89: 41 | R89: F | S89: F/W | U89: 25 | V89: F | W89: BLK F | Y89: 88 | Z89: F | AA89: F/W | AC89: 19 | AD89: M | AE89: M/W | AG89: 5 | AH89: M | AI89: C/W | AK89: 25 | AL89: f | AM89: f/w | AO89: 54 | AP89: f | AQ89: F/W
A90: 65 | B90: M | C90: A/E | E90: 87 | F90: F | G90: F/W | I90: 28 | J90: F | K90: A/E | M90: 3 | N90: F | O90: C/W | Q90: 71 | R90: F | S90: F/W | U90: 42 | V90: F | W90: BLK F | Y90: 32 | Z90: F | AA90: F/W | AC90: 75 | AD90: M | AE90: M/W | AG90: 3 MTH | AH90: F | AI90: C/W | AK90: 15 | AL90: f | AM90: f/w | AO90: 54 | AP90: f | AQ90: F/W
A91: 65 | B91: M | C91: A/E | E91: 86 | F91: F | G91: A/E | I91: 83 | J91: F | K91: A/E | M91: 1 | N91: M | O91: C/W | Q91: 21 | R91: F | S91: F/W | U91: 23 | V91: F | W91: BLK F | Y91: 40 | Z91: F | AA91: F/W | AC91: 35 | AD91: M | AE91: M/W | AG91: 3 | AH91: M | AI91: C/W | AK91: 36 | AL91: f | AM91: f/w | AO91: 44 | AP91: f | AQ91: F/W
A92: 65 | B92: M | C92: A/E | E92: 85 | F92: F | G92: F/W | I92: 50 | J92: F | K92: A/E | M92: 4 | N92: F | O92: C/W | Q92: 80 | R92: F | S92: F/W | U92: 42 | V92: F | W92: BLK F | Y92: 26 | Z92: F | AA92: F/W | AC92: 81 | AD92: M | AE92: M/W | AG92: 3 MTH | AH92: M | AI92: C/W | AK92: 77 | AL92: f | AM92: f/w | AO92: 47 | AP92: f | AQ92: F/W
A93: 71 | B93: F | C93: A/E | E93: 84 | F93: F | G93: F/W | I93: 75 | J93: F | K93: A/E | M93: 5 | N93: M | O93: C/W | Q93: 36 | R93: F | S93: F/W | U93: 41 | V93: F | W93: BLK F | Y93: 18 | Z93: F | AA93: F/W | AC93: 32 | AD93: M | AE93: M/W | AG93: 5 | AH93: M | AI93: C/W | AK93: 42 | AL93: f | AM93: f/w | AO93: 71 | AP93: f | AQ93: F/W
A94: 78 | B94: F | C94: A/E | E94: 80 | F94: F | G94: A/E | I94: 30 | J94: F | K94: A/E | M94: 9 MTHS | N94: M | O94: C/W | Q94: 63 | R94: F | S94: F/W | U94: 22 | V94: F | W94: BLK F | Y94: 45 | Z94: F | AA94: F/W | AC94: 17 | AD94: M | AE94: M/W | AG94: 7 | AH94: M | AI94: C/W | AK94: 18 | AL94: f | AM94: f/w | AO94: 65 | AP94: f | AQ94: F/W
A95: 65 | B95: M | C95: A/E | E95: 79 | F95: F | G95: A/E | I95: 26 | J95: F | K95: A/E | M95: 1 | N95: M | O95: C/W | Q95: 56 | R95: F | S95: F/W | U95: 46 | V95: F | W95: BLK F | Y95: 47 | Z95: F | AA95: F/W | AC95: 32 | AD95: M | AE95: M/W | AG95: 4 | AH95: F | AI95: C/W | AK95: 48 | AL95: f | AM95: f/w | AO95: 53 | AP95: f | AQ95: F/W
A96: 79 | B96: F | C96: A/E | E96: 79 | F96: F | G96: A/E | I96: 79 | J96: M | K96: A/E | M96: 1 | N96: M | O96: C/W | Q96: 54 | R96: F | S96: F/W | U96: 22 | V96: F | W96: BLK F | Y96: 58 | Z96: F | AA96: F/W | AC96: 14 | AD96: M | AE96: M/W | AG96: 12 | AH96: F | AI96: C/W | AK96: 38 | AL96: f | AM96: f/w | AO96: 31 | AP96: f | AQ96: F/W
A97: 67 | B97: M | C97: A/E | E97: 78 | F97: M | G97: A/E | I97: 37 | J97: M | K97: A/E | M97: 1 | N97: F | O97: C/W | Q97: 51 | R97: F | S97: F/W | U97: 33 | V97: F | W97: BLK F | Y97: 52 | Z97: F | AA97: F/W | AC97: 34 | AD97: F | AE97: F/W | AG97: 2 | AH97: M | AI97: C/W | AK97: 18 | AL97: f | AM97: f/w | AO97: 17 | AP97: f | AQ97: F/W
A98: 68 | B98: M | C98: A/E | E98: 78 | F98: F | G98: F/W | I98: 1 | J98: F | K98: A/E | M98: 9 MTHS | N98: F | O98: C/W | Q98: 54 | R98: F | S98: F/W | U98: 15 | V98: F | W98: BLK F | Y98: 41 | Z98: F | AA98: F/W | AC98: 73 | AD98: F | AE98: F/W | AG98: 9 | AH98: M | AI98: C/W | AK98: 76 | AL98: f | AM98: f/w | AO98: 32 | AP98: f | AQ98: F/W
A99: 68 | B99: M | C99: A/E | E99: 77 | F99: M | G99: M/W | I99: 72 | J99: F | K99: A/E | M99: 4 | N99: F | O99: C/W | Q99: 16 | R99: F | S99: F/W | U99: 31 | V99: F | W99: BLK F | Y99: 45 | Z99: F | AA99: F/W | AC99: 69 | AD99: F | AE99: F/W | AG99: 3 MTH | AH99: F | AI99: C/W | AK99: 36 | AL99: f | AM99: f/w | AO99: 33 | AP99: f | AQ99: F/W
A100: 68 | B100: M | C100: A/E | E100: 77 | F100: F | G100: F/W | I100: 53 | J100: F | K100: A/E | M100: 2 | N100: M | O100: C/W | Q100: 58 | R100: F | S100: F/W | U100: 34 | V100: F | W100: BLK F | Y100: 63 | Z100: F | AA100: F/W | AC100: 61 | AD100: F | AE100: F/W | AG100: 5 MTH | AH100: F | AI100: C/W | AK100: 15 | AL100: f | AM100: f/w | AO100: 17 | AP100: f | AQ100: F/W
